File: python_archive/7ipython/autodata1.csv
Stress(MPa),Strain(%)
0,0
3.55,0.023
7.86,0.051
12.2,0.079
16.2,0.105332456
20.3,0.131665569
24.6,0.159644503
29.1,0.189269256
33.5,0.21724819
37.5,0.243581303
41.6,0.269914417
45.9,0.297893351
50.4,0.327518104
54.7,0.355497038
58.8,0.381830151
63.1,0.409809085
67.4,0.437788018
71.7,0.465766952
76,0.493745885
80.3,0.521724819
84.4,0.548057933
88.7,0.576036866
93.3,0.605661619
97.6,0.633640553
102,0.659973667
106,0.686306781
110,0.715931534
115,0.743910467
119,0.771889401
123,0.798222515
127,0.824555629
132,0.854180382
136,0.882159315
140,0.910138249
144,0.936471363
148,0.962804477
153,0.99242923
157,1.020408163
161,1.048387097
166,1.074720211
170,1.101053325
174,1.130678078
178,1.158657011
183,1.186635945
187,1.212969059
191,1.240947992
195,1.268926926
200,1.296905859
204,1.324884793
208,1.351217907
212,1.37755102
217,1.407175774
221,1.435154707
225,1.463133641
229,1.489466754
233,1.515799868
238,1.545424621
242,1.573403555
247,1.601382488
251,1.627715602
255,1.655694536
259,1.683673469
264,1.713298223
268,1.739631336
272,1.76761027
276,1.793943384
281,1.823568137
285,1.85154707
289,1.879526004
294,1.905859118
298,1.932192232
302,1.960171165
306,1.989795918
310,2.016129032
315,2.042462146
319,2.07044108
323,2.098420013
328,2.128044766
332,2.15437788
336,2.182356814
340,2.208689928
345,2.238314681
349,2.266293614
353,2.294272548
351.4025067,2.320605662
349.2417748,2.346938776
346.4991817,2.376563529
344.5827988,2.404542462
344.2608138,2.432521396
343.7614919,2.45885451
343.169824,2.486833443
342.8151502,2.514812377
342.6615126,2.54279131
343.6184782,2.570770244
342.7693858,2.595457538
342.5683495,2.625082291
342.5683495,2.653061224
342.6124794,2.681040158
344.450409,2.709019092
344.7960935,2.735352205
346.1559489,2.763331139
347.5689237,2.792955892
348.2905297,2.820934826
349.8113777,2.847267939
349.586642,2.873601053
350.1243733,2.901579987
350.5468765,2.93120474
350.8173766,2.959183673
352.1461776,2.985516787
351.6296941,3.011849901
352.1682426,3.039828835
353.0663683,3.069453588
352.6438651,3.097432521
352.5997352,3.123765635
351.6403179,3.150098749
351.9263452,3.178077683
352.6463168,3.207702436
352.8906658,3.235681369
353.6956283,3.262014483
353.1497248,3.288347597
353.8607069,3.31797235
354.6329806,3.345951284
353.4275799,3.373930217
353.6874561,3.400263331
353.0222384,3.426596445
354.2725862,3.456221198
355.1110548,3.485845951
355.4297709,3.512179065
355.6986366,3.538512179
355.1135065,3.564845293
355.1372059,3.594470046
355.8065097,3.62244898
355.6675822,3.650427913
355.4959658,3.676761027
355.104517,3.703094141
356.5632562,3.732718894
357.6109333,3.760697828
357.3118305,3.788676761
357.9239289,3.815009875
357.5757928,3.841342989
358.5025213,3.870967742
357.9672416,3.898946675
354.9680412,3.926925609
351.4425505,3.954904542
350.6980623,3.981237656
352.1837698,4.010862409
353.4668065,4.038841343
353.479882,4.066820276
354.0503022,4.09315339
354.2987373,4.119486504
356.1652697,4.147465438
356.6073862,4.177090191
356.5305674,4.203423305
356.984125,4.231402238
356.5983967,4.257735352
357.5055119,4.287360105
358.2450967,4.315339039
358.0865559,4.343317972
357.7915391,4.369651086
356.8231325,4.3959842
355.1944113,4.425608953
351.8822153,4.453587887
352.1862215,4.48156682
353.8827719,4.507899934
354.3608461,4.534233048
355.0693766,4.563857801
355.441212,4.591836735
355.485342,4.619815668
355.370931,4.646148782
355.5776879,4.672481896
356.1317636,4.702106649
356.0990748,4.730085583
356.9972005,4.758064516
356.9988349,4.78439763
357.5145013,4.810730744
357.7719258,4.840355497
358.0334365,4.868334431
358.8849806,4.896313364
359.2216756,4.922646478
359.6490821,4.948979592
359.8999689,4.978604345
359.637641,5.008229098
359.959626,5.034562212
358.6479866,5.060895326
358.1413097,5.088874259
357.1402141,5.116853193
356.4382214,5.146477946
357.7784636,5.17281106
357.3494227,5.199144174
357.2350118,5.227123107
355.0775488,5.255102041
351.1009522,5.284726794
353.1456387,5.311059908
353.7046178,5.337393022
354.4662676,5.365371955
353.9023852,5.394996708
353.3262445,5.422975642
354.2529729,5.449308756
353.3434062,5.47564187
353.6719289,5.503620803
353.2183714,5.533245556
350.2894519,5.56122449
350.700514,5.587557604
350.8770337,5.615536537
352.0317667,5.643515471
353.7046178,5.671494404
354.3910833,5.699473338
355.8220369,5.727452271
355.0293327,5.752139566
355.2785851,5.781764319
355.9470717,5.809743252
355.5360096,5.837722186
356.5436429,5.8640553
355.8808768,5.890388413
356.7397759,5.920013167
357.9762311,5.9479921
358.1176103,5.975971034
358.4894457,6.002304147
357.0208999,6.028637261
355.7362288,6.058262014
356.5853212,6.087886768
356.6694949,6.114219882
357.2570767,6.140552995
356.787992,6.168531929
357.2652489,6.196510862
355.3970821,6.226135616
352.1927592,6.252468729
352.5931974,6.280447663
352.6152624,6.305134957
354.4442026,6.33475971
355.7599282,6.362738644
355.218928,6.390717577
355.3554038,6.417050691
354.2390802,6.443383805
354.5390002,6.473008558
353.916278,6.502633311
353.1145843,6.528966425
353.2559635,6.555299539
352.4787865,6.583278473
353.5705935,6.612903226
354.3673839,6.640882159
353.8631586,6.668861093
354.0167961,6.695194207
353.7422099,6.721527321
354.5496241,6.751152074
354.5545274,6.779131007
353.3785466,6.807109941
350.993079,6.833443055
347.9538348,6.859776169
348.1891944,6.889400922
348.5659332,6.917379855
348.8715738,6.943712969
349.8399804,6.971691903
350.2338809,6.998025016
351.4270233,7.02764977
351.7302122,7.055628703
351.574123,7.083607637
351.6207046,7.10994075
351.1099416,7.137919684
351.7988588,7.165898618
351.7964071,7.193877551
351.6713723,7.221856485
351.596188,7.248189598
351.3828934,7.276168532
351.5545097,7.305793285
351.2505036,7.333772219
351.3918828,7.360105332
351.5634992,7.386438446
351.8936564,7.41441738
351.9524963,7.442396313
351.7547289,7.470375247
352.0603694,7.49835418
351.8912047,7.524687294
352.3799028,7.552666228
352.8555253,7.580645161
352.39543,7.608624095
352.7492866,7.636603028
351.4842288,7.664581962
350.74873,7.690915076
350.1766754,7.720539829
349.9740047,7.748518762
350.6980623,7.776497696
350.2052782,7.80283081
350.3793462,7.829163924
350.7421922,7.858788677
350.537887,7.88676761
349.2197098,7.914746544
346.4133735,7.941079658
351.385345,7.969058591
354.0592916,7.997037525
355.6504206,8.025016458
357.3363471,8.052995392
357.6419877,8.079328506
358.6912993,8.107307439
359.4178086,8.135286373
359.6662437,8.163265306
361.1764678,8.19124424
360.5905205,8.217577354
361.3897625,8.245556287
362.0410875,8.273535221
361.9307627,8.303159974
362.9416648,8.329493088
362.4505151,8.355826201
362.8485017,8.383805135
363.5594838,8.413429888
363.3135003,8.441408822
364.2443148,8.467741935
363.456514,8.494075049
364.1495172,8.522053983
364.6472047,8.551678736
364.1299039,8.57965767
364.8694888,8.605990783
364.1740339,8.632323897
364.9266942,8.660302831
365.7275707,8.689927584
365.0280296,8.717906517
365.9057248,8.744239631
365.2168076,8.770572745
365.9318759,8.800197498
366.4777794,8.828176432
365.9604786,8.856155365
366.6256964,8.882488479
365.747184,8.908821593
366.594642,8.938446346
367.0016179,8.968071099
366.4892205,8.994404213
367.2083748,9.020737327
366.5063821,9.047070441
367.3693673,9.076695194
367.8229249,9.104674128
367.3121619,9.132653061
367.9790141,9.158986175
367.1356422,9.185319289
368.1465443,9.214944042
368.4963148,9.244568795
367.9373358,9.270901909
368.4758843,9.297235023
368.0623706,9.325213957
368.9474207,9.35319289
368.8967531,9.382817643
368.5224659,9.410796577
369.1713393,9.437129691
368.8199343,9.463462804
369.4974104,9.493087558
369.5725947,9.521066491
369.4140538,9.549045425
369.7924271,9.575378539
369.6494134,9.601711652
370.221468,9.631336406
370.0653788,9.659315339
370.0825405,9.685648453
370.3538578,9.713627386
370.0760027,9.7399605
370.6635845,9.769585253
370.5933035,9.797564187
370.5140331,9.82554312
371.013355,9.851876234
370.8621692,9.878209348
371.4227826,9.907834101
371.3925455,9.935813035
371.3198128,9.963791968
371.4824398,9.991770902
371.3770183,10.01810402
371.8346619,10.04772877
371.5290214,10.0757077
371.9752239,10.10204082
371.9204701,10.13001975
372.1607331,10.15635286
372.393641,10.1843318
372.2310141,10.21231073
372.6837544,10.24028966
372.5979462,10.26662278
372.6862061,10.29460171
372.8185958,10.32258065
372.6093873,10.3522054
373.3841126,10.38018433
372.9567062,10.40651745
373.289315,10.43285056
373.3931021,10.46247531
373.2786912,10.49045425
373.9079512,10.51843318
373.7976264,10.54476629
373.7976264,10.57274523
373.9185751,10.60072416
373.9365539,10.63034891
374.636095,10.65668203
374.1915268,10.68301514
374.3304544,10.71099408
374.4162626,10.73897301
374.3108411,10.76859776
375.0259093,10.79493088
374.4644786,10.82126399
374.8297763,10.84924292
375.1313308,10.87722186
374.9311117,10.90684661
375.8774534,10.93317972
375.0937386,10.95951284
375.4876391,10.98913759
375.9150456,11.01711652
375.461488,11.04509546
376.042532,11.07307439
375.2939577,11.0994075
375.6371905,11.12738644
376.1373296,11.15536537
375.938745,11.18499013
376.5132512,11.21132324
375.8619262,11.23765635
376.4691213,11.26563529
377.030552,11.29361422
376.2362134,11.32159315
377.0264659,11.34957209
376.0490698,11.3759052
376.8965278,11.40388413
377.3035038,11.43350889
376.8041818,11.46148782
377.5298739,11.48782093
376.5794461,11.51415405
377.4293558,11.54213298
377.6737048,11.57175774
377.3214826,11.59973667
377.8534934,11.62606978
377.1073708,11.6524029
377.9172366,11.68202765
378.0079481,11.71000658
377.5192501,11.73798552
378.0872185,11.76431863
377.6867803,11.79065174
378.2498455,11.8202765
378.5334211,11.84825543
378.0782291,11.87623436
378.5489483,11.90256748
378.0234753,11.92890059
378.6878759,11.95852535
378.9542898,11.9881501
378.4279996,12.01448321
378.8594922,12.04246215
378.4786673,12.06879526
378.9493865,12.09842001
379.1348957,12.12639895
378.5710133,12.15437788
379.0531736,12.18071099
378.5579377,12.20704411
379.5042795,12.23666886
379.5328822,12.26464779
379.4274607,12.29262673
379.5353339,12.31895984
379.5157206,12.34529296
379.8851044,12.37491771
379.8499639,12.40289664
379.8695772,12.43087558
380.0411936,12.45720869
379.7306496,12.4835418
380.1825728,12.51316656
380.1670456,12.54114549
380.0697963,12.56912442
380.5233538,12.59545754
380.261026,12.62343647
380.3893296,12.6514154
380.2544882,12.68104016
380.3076075,12.70901909
380.6181515,12.73535221
380.4261046,12.76168532
380.875576,12.79131007
380.457159,12.81928901
380.7480896,12.84726794
380.8821138,12.87360105
380.9589326,12.90157999
381.2277982,12.93120474
380.8600488,12.95918367
381.3659085,12.98716261
381.2915414,13.0118499
381.3242303,13.03982883
381.5089222,13.06780777
381.2449598,13.0957867
381.8570582,13.12541145
381.5555038,13.15009875
381.6609252,13.17807768
381.5555038,13.20605662
381.5293527,13.23568137
382.1389994,13.2636603
382.0172335,13.28999342
381.8129283,13.31632653
381.8701338,13.3475971
382.0066097,13.37557604
382.7216779,13.40190915
382.318788,13.42824226
382.4953077,13.4562212
382.3588318,13.48420013
382.2158182,13.51217907
382.8189272,13.540158
382.1038589,13.56649111
382.6097186,13.59447005
382.536986,13.62244898
382.563137,13.65207373
383.4964032,13.67840685
382.396424,13.70473996
382.9349725,13.73271889
382.9946296,13.76234365
382.8867565,13.79032258
383.6900846,13.81665569
382.6889891,13.84298881
383.0297701,13.87261356
383.2128276,13.9005925
383.2545059,13.92857143
383.8380015,13.95655036
383.0763517,13.98123766
383.5013066,14.01086241
383.9965424,14.03884134
383.4236706,14.06682028
384.1256633,14.09315339
383.2169137,14.1194865
383.909917,14.14911126
384.2335364,14.17709019
383.43266,14.20506912
384.1174911,14.23304806
383.4130467,14.25938117
383.9965424,14.28736011
384.3749156,14.31698486
383.8551632,14.34496379
384.3700123,14.37129691
383.721139,14.39763002
384.2670425,14.42725477
384.7026212,14.45523371
384.1697932,14.48321264
384.8766892,14.50954575
383.8772281,14.53587887
384.665029,14.56550362
384.9224536,14.59348255
384.3193446,14.62146149
384.8783237,14.6477946
384.1174911,14.67412772
384.7688161,14.70375247
385.1406516,14.7317314
384.7974188,14.75971034
385.0613811,14.78604345
384.6143613,14.81402238
385.2861169,14.84364714
385.5803164,14.87162607
384.5971997,14.899605
385.1717059,14.92593812
384.6830079,14.95227123
385.5100354,14.98189598
385.3057302,15.00987492
384.9510563,15.03785385
385.246073,15.06418697
385.3098163,15.09052008
385.7854388,15.12014483
385.5721442,15.14812377
385.3539462,15.1761027
385.6930928,15.20243581
385.3433223,15.23041475
385.6448768,15.25839368
385.4552816,15.28801843
385.4373027,15.31435155
385.8099554,15.34068466
385.6244463,15.36866359
385.9374419,15.39828835
385.5410898,15.42626728
385.5370037,15.45424621
385.941528,15.48057933
385.7241472,15.50691244
386.06738,15.5365372
385.8271171,15.56451613
385.6775656,15.59249506
385.7895249,15.61882818
385.8957636,15.64516129
386.1662637,15.67478604
385.7919766,15.70276498
386.163812,15.73074391
386.1531882,15.75707702
386.1662637,15.78341014
386.3182668,15.81303489
386.0869933,15.84265964
386.6655856,15.86899276
386.4408499,15.89697169
386.3836444,15.92330481
386.3754722,15.95292956
386.1948664,15.98090849
387.0464105,16.00888743
386.6328968,16.03522054
386.4898832,16.06155365
386.4261399,16.09117841
386.4849798,16.12080316
387.1853381,16.14713627
386.7138017,16.17346939
386.7848999,16.20144832
386.7710071,16.22942725
386.6173696,16.25740619
387.4092566,16.28538512
386.6990917,16.31171824
386.8461914,16.33969717
387.1166915,16.3676761
386.8020615,16.39730086
387.5040542,16.42363397
386.6851989,16.44996708
387.1918758,16.47794602
387.195962,16.50757077
386.9581507,16.5355497
387.6160135,16.56188282
386.7252428,16.58821593
387.0464105,16.61784068
387.5089575,16.64581962
387.2883079,16.67379855
387.7443171,16.70177749
386.8878697,16.72646478
387.4468487,16.75608953
387.9159335,16.78406847
387.3855572,16.8120474
387.8407492,16.83838051
386.9058486,16.86471363
387.440311,16.89433838
387.7508549,16.92231731
387.4076221,16.95194207
388.0540438,16.97827518
387.0619377,17.00460829
387.6911978,17.03258723
387.9641495,17.06221198
387.4443971,17.09019092
387.9706873,17.11652403
387.0619377,17.14285714
387.6911978,17.1724819
388.0850982,17.20046083
387.5923141,17.22843976
388.1333142,17.25477288
387.3283517,17.28110599
388.0810121,17.31073074
388.091636,17.33870968
387.7614788,17.36668861
388.1774442,17.39302172
387.4803548,17.41935484
388.1447553,17.44897959
388.2019608,17.47695853
387.7157144,17.50493746
388.2305635,17.53127057
387.7443171,17.55924951
388.3866527,17.58722844
388.3686738,17.61685319
387.8186842,17.64318631
388.3229095,17.67116524
387.7287899,17.69749835
388.2215741,17.72712311
388.3956421,17.75510204
387.858728,17.78308097
388.3605016,17.80941409
388.0082795,17.8357472
388.532118,17.86372614
388.5337525,17.89335089
388.1864336,17.919684
388.5713446,17.94766294
388.0589472,17.97399605
388.4569337,18.0036208
388.9415457,18.02995392
388.4479443,18.05793285
388.4152554,18.08591178
388.0319789,18.1122449
388.5337525,18.14186965
388.2632524,18.16984858
388.4332343,18.19782752
388.4855364,18.22416063
388.3760288,18.25049375
388.6792178,18.2801185
388.3032962,18.30974325
388.602399,18.33607637
388.7454127,18.36240948
388.8925124,18.38874259
388.5272147,18.41836735
388.5035153,18.44634628
388.694745,18.47432521
388.5868718,18.50065833
388.5231286,18.52699144
388.6334534,18.55661619
388.5272147,18.58624095
389.0641288,18.61257406
388.7781015,18.63890718
388.8353069,18.66688611
388.8418447,18.69486504
388.5100531,18.7244898
389.1483025,18.75246873
388.5231286,18.77880184
388.8712647,18.80513496
388.7364232,18.83475971
388.5999473,18.86273864
389.3746727,18.89071758
388.8116075,18.91705069
388.8843402,18.94502962
389.135227,18.97300856
388.742961,19.00098749
389.5618163,19.02732061
388.9938478,19.05365372
388.8181453,19.08327847
388.9497179,19.11125741
388.7584882,19.13923634
389.5748918,19.16721527
388.813242,19.19354839
388.868813,19.22152732
389.3730383,19.24950625
389.0665804,19.27748519
389.5708057,19.30546412
388.8573719,19.33179724
388.961159,19.35977617
389.3656833,19.38940092
389.2798751,19.41737986
389.9843194,19.44371297
388.6130229,19.47004608
388.9636106,19.49802502
389.4081787,19.52600395
389.0976348,19.55398288
389.6827649,19.58196182
388.6571528,19.60829493
389.0714838,19.63627386
389.5732574,19.66589862
389.1147965,19.69387755
389.8502952,19.72021066
388.8402103,19.74654378
389.3730383,19.77616853
389.5732574,19.80414747
389.0641288,19.8321264
389.542203,19.85845951
388.7012827,19.88479263
389.6345489,19.91441738
389.5708057,19.94239631
389.1589264,19.97037525
389.6631516,19.99670836
389.0976348,20.02304147
389.6280112,20.05266623
389.5552785,20.08064516
389.3068434,20.10862409
389.379576,20.13495721
388.9652451,20.16129032
389.4032754,20.19091508
389.6214734,20.21889401
389.0183644,20.24687294
389.5838812,20.27320606
389.0142783,20.30118499
389.694206,20.32916392
389.808617,20.35714286
389.2431001,20.38512179
389.6280112,20.41310072
389.1924324,20.43943384
389.5748918,20.46905859
389.97533,20.49703752
389.0404294,20.52337064
389.6100323,20.55134957
389.2030563,20.57768269
389.7244432,20.60566162
389.6100323,20.63528637
389.2937678,20.66161949
389.4956214,20.6879526
389.1017209,20.71593153
389.5086969,20.74555629
389.5511924,20.77353522
389.3329944,20.80151415
389.520138,20.82784727
389.1965186,20.85418038
389.5160519,20.88380513
389.2627134,20.91178407
389.2954023,20.939763
389.4188026,20.96609612
389.0690321,20.99242923
389.3591455,21.02205398
389.1417648,21.05003292
389.2888645,21.07801185
389.4384159,21.10434496
389.4147165,21.13067808
389.6018601,21.16030283
389.2381968,21.18828176
389.4825458,21.2162607
389.2561757,21.24259381
389.3109295,21.26892693
389.1082587,21.29855168
389.1107104,21.32653061
389.7751109,21.35450955
389.3289083,21.38084266
389.3370805,21.40717577
389.4760081,21.43680053
389.1196998,21.46642528
389.9099523,21.49275839
389.5242241,21.51909151
389.4588464,21.54707044
389.3656833,21.57504937
389.253724,21.60467413
390.0325355,21.63100724
389.5086969,21.65734036
389.5773435,21.68531929
389.7465082,21.71329822
389.157292,21.74292298
389.8658224,21.76925609
389.2226696,21.7955892
389.3133811,21.82356814
389.4890836,21.85319289
389.3861138,21.88117182
389.96062,21.90750494
389.2365624,21.93383805
389.1965186,21.9634628
389.5356652,21.99144174
389.34607,22.01942067
389.8323164,22.04575379
389.035526,22.07373272
389.1858947,22.10171165
389.6280112,22.12969059
389.3656833,22.15766952
390.0039327,22.18564845
389.0249022,22.21033575
389.5046108,22.2399605
389.764487,22.26793943
389.1858947,22.29591837
389.8748118,22.32225148
388.8050698,22.3485846
389.3068434,22.37820935
389.5446546,22.40618828
389.3419839,22.43416722
389.905049,22.46050033
388.9064052,22.48683344
389.4735564,22.5164582
389.7489598,22.54608295
389.1744536,22.57241606
389.8257786,22.600395
388.7388749,22.62672811
389.5086969,22.65470704
389.7448737,22.6843318
389.0289883,22.71231073
389.401641,22.73864384
389.0469671,22.76497696
389.5225897,22.79295589
389.6737755,22.82258065
389.0690321,22.84891376
389.3861138,22.87524687
389.0273538,22.90157999
389.4433192,22.93120474
389.5863329,22.96082949
388.9766861,22.98716261
389.3615972,23.01349572
388.7323371,23.04147465
389.1483025,23.07109941
389.4433192,23.09907834
388.8622752,23.12705727
389.1286892,23.15339039
388.813242,23.1797235
389.2447346,23.20934826
389.2913162,23.23732719
389.1221515,23.26530612
389.590419,23.29163924
389.0003856,23.31797235
389.4212543,23.3475971
389.1548403,23.37557604
389.0249022,23.40190915
389.1589264,23.42988808
388.8001664,23.4562212
389.0624943,23.48584595
389.2431001,23.51382488
389.2006047,23.54180382
389.1858947,23.56813693
389.0641288,23.59611587
389.3068434,23.6240948
388.6440773,23.65207373
388.9987511,23.68005267
389.0273538,23.7080316
388.6906589,23.73436471
388.813242,23.76234365
388.694745,23.7919684
388.9064052,23.81994733
388.8491997,23.84628045
388.7633915,23.87261356
389.1196998,23.9005925
388.694745,23.92857143
389.1017209,23.95655036
388.9636106,23.98288348
388.580334,24.01086241
388.6816694,24.03884134
388.3670394,24.0684661
388.7781015,24.09479921
388.6636906,24.12277814
388.5737963,24.14911126
388.7960803,24.17873601
388.3980938,24.20671494
389.1523886,24.23469388
388.5648068,24.26102699
388.6702283,24.28736011
388.7298855,24.31698486
388.798532,24.34496379
389.035526,24.37294273
388.3980938,24.39927584
388.6179262,24.42725477
388.4634715,24.45523371
388.4217932,24.48321264
388.8001664,24.51119157
388.3539639,24.53752469
388.3686738,24.56550362
388.4969775,24.59348255
388.35805,24.62146149
389.1989702,24.64944042
388.2060469,24.67577354
388.4307826,24.70375247
388.4749126,24.7317314
388.3008445,24.76135616
388.8091559,24.78768927
387.8758897,24.81402238
388.4177071,24.84364714
388.4920742,24.87162607
388.2542629,24.899605
388.9701484,24.92593812
387.9175679,24.95227123
388.3866527,24.98025016
388.6334534,25.00987492
388.0564955,25.03785385
388.6195606,25.06418697
387.7263383,25.09052008
388.2853173,25.11849901
388.4128038,25.14812377
387.7859954,25.1761027
388.3686738,25.20243581
387.5326569,25.22876893
388.1512931,25.25839368
388.4332343,25.28637261
387.8342114,25.31435155
388.3515122,25.34068466
387.4076221,25.36701777
388.476547,25.39664253
388.239553,25.42626728
387.4754515,25.45260039
388.0720227,25.47893351
387.4157944,25.50526662
387.7238866,25.53489138
388.147207,25.56287031
387.488527,25.59084924
387.8848791,25.61718236
387.2335541,25.64351547
387.7639304,25.67314022
387.9796767,25.70111916
387.3790194,25.72909809
387.8096948,25.7554312
387.0398728,25.78341014
387.6585089,25.81138907
387.7394138,25.84101382
387.2932112,25.86899276
387.5964002,25.89532587
387.0643894,25.92165899
387.5898624,25.95128374
387.6078413,25.97926267
387.2376402,26.00724161
387.6405301,26.03357472
386.9957428,26.05990783
387.3299862,26.08953259
387.3299862,26.11751152
387.0929921,26.14549045
387.5391947,26.17182357
386.8396537,26.19815668
387.3013834,26.22778144
386.9426235,26.25576037
386.9892051,26.2837393
387.2400919,26.31007242
386.9033969,26.33805135
387.321814,26.36603028
386.6435207,26.39565504
386.7824482,26.42198815
386.8396537,26.44996708
386.6614995,26.4763002
387.0619377,26.50592495
386.452291,26.5355497
386.5601641,26.56188282
386.4980554,26.58986175
386.5691536,26.61454905
386.6721234,26.64252798
386.3329768,26.67215273
386.4915176,26.69848585
386.1989525,26.72646478
386.2831263,26.75279789
386.6655856,26.78242265
386.2185658,26.81040158
386.6173696,26.83838051
386.1417471,26.86471363
386.4187849,26.89104674
386.0207984,26.92067149
385.8933119,26.94865043
386.4171505,26.97662936
386.0207984,27.00296248
385.9374419,27.03094141
385.9088391,27.05892034
385.6971789,27.0885451
386.6083802,27.11487821
385.8843225,27.14121132
385.8336548,27.16919026
385.8516337,27.19716919
385.6203602,27.22679394
386.4629149,27.25312706
385.3563979,27.27946017
385.6089191,27.3074391
385.6955445,27.33706386
385.386635,27.36504279
386.3574934,27.39137591
385.1341138,27.41935484
385.6113708,27.44733377
385.5541653,27.47531271
385.4087,27.50329164
385.8671609,27.53127057
384.9183675,27.55760369
385.1251244,27.58558262
385.1512754,27.61520737
384.9494219,27.64318631
385.4969598,27.66951942
384.8194838,27.69585253
385.0654672,27.72383147
385.3514945,27.7518104
384.6960834,27.77978934
385.3008268,27.80776827
384.3544851,27.83410138
384.9224536,27.86208032
384.883227,27.89170507
384.3700123,27.919684
384.835011,27.94601712
383.9720258,27.97235023
384.4010667,28.00197498
384.6339746,28.02995392
383.817571,28.05793285
384.4386589,28.08426596
383.5470709,28.11059908
384.3087207,28.14022383
384.3062691,28.16820276
383.6745574,28.1961817
384.035769,28.22251481
383.188311,28.24884793
383.5380815,28.27847268
383.8551632,28.30645161
383.2961841,28.33443055
383.5315437,28.36076366
382.8916598,28.38709677
383.3868956,28.41672153
383.4105951,28.44634628
382.7944105,28.47267939
383.1114922,28.49901251
382.5745781,28.52699144
382.7020646,28.55661619
382.8164755,28.58459513
382.3367669,28.61257406
382.4005101,28.63890718
382.0196852,28.66524029
382.3367669,28.69486504
382.2860992,28.72284398
382.0858801,28.75082291
381.9976202,28.77715602
381.6151609,28.80348914
382.2354315,28.83311389
381.6960657,28.86109282
381.5865582,28.88907176
381.9273392,28.91540487
380.9965247,28.94173799
381.0185897,28.97136274
380.9769114,28.99934167
380.805295,29.02732061
380.9278782,29.05365372
380.583011,29.08163265
380.5143644,29.10961159
380.4506212,29.13923634
380.364813,29.16721527
380.2634776,29.19354839
379.7110363,29.2198815
380.1891105,29.24950625
379.3081465,29.27748519
379.2444032,29.30546412
379.328577,29.33179724
379.2689199,29.35813035
379.3081465,29.3877551
378.5538516,29.41573404
378.8594922,29.44371297
378.4876568,29.47004608
378.1109179,29.4963792
378.0300131,29.52600395
377.4579585,29.55398288
377.8804617,29.58196182
377.4685824,29.60829493
377.0044009,29.63627386
376.7379869,29.66589862
376.4323464,29.69387755
376.8769145,29.72185648
376.1659324,29.7481896
375.9959504,29.77452271
375.5824367,29.80414747
375.483553,29.83377222
375.6461799,29.86010533
375.0038443,29.88643845
374.8232385,29.91441738
374.5878789,29.94239631
374.0248138,29.97037525
374.4489514,29.99835418
373.6676883,30.02468729
373.3358966,30.05266623
373.067031,30.08064516
372.4753631,30.11026991
373.1724525,30.13660303
371.7243371,30.16293614
371.7071755,30.1925609
371.6189156,30.22053983
370.8180392,30.24851876
371.1302176,30.2764977
370.0016356,30.30118499
369.7744482,30.33080974
369.4867865,30.35878868
368.9139147,30.38676761
369.1345643,30.41474654
367.582662,30.44107966
367.2288053,30.46905859
367.1380938,30.49703752
365.9539408,30.52501646
366.0528246,30.55299539
364.3693496,30.57768269
364.1250006,30.60730744
363.7245624,30.63693219
362.1930906,30.66491113
361.8343306,30.69124424
359.6531682,30.71757735
358.9184867,30.74555629
357.6199228,30.77518104
355.5270202,30.80315997
354.4817948,30.82949309
351.6378663,30.8558262
350.0385651,30.88545095
348.2382276,30.90026333